Workbook

Sheet Sheet1

Sheet Assumptions
A1: DECO CREATIVE CENTER - FINANCIAL ASSUMPTIONS | D1: EDITABLE INPUTS
D2: All values can be edited
A3: FACILITY INFORMATION (RENTAL) | D3: Blue cells = formulas (auto-calculate)
A4: Square Footage | B4: 3000 | D4: White cells = your inputs
A5: Base Rent ($/sf/year) | B5: 15
A6: NNN - Triple Net ($/sf/year) | B6: 3
A7: Total Annual Rent | B7: =B4*(B5+B6) -> 54000
A8: Monthly Rent | B8: =B7/12 -> 4500
A10: TIMELINE
A11: Opening Date | B11: 46082
A12: Year 1 Operating Months | B12: 10
A13: Class Sessions Year 1 | B13: 6
A14: Class Sessions Year 2+ | B14: 12
A16: FINANCING (WORKING CAPITAL LOAN)
A17: Startup Costs Total | B17: ='Startup Costs'!B28 -> 80875
A18: Operating Reserve (months) | B18: 3
A19: Operating Reserve Amount | B19: =Expenses!B35/12*B18 -> 0
A20: Total Loan Amount | B20: =B17+B19 -> 80875
A21: Loan Term (years) | B21: 10
A22: Interest Rate | B22: 0.1225
A23: Monthly Payment | B23: =-PMT(B22/12,B21*12,B20) -> 1172.0394
A25: ENROLLMENT CAPACITY
A26: Year 1 Capacity % | B26: 0.6
A27: Annual Growth % | B27: 0.2
A28: Drop-in Rate % | B28: 0.05
A30: STAFF COMPENSATION
A31: Owner 1 Annual Salary | B31: 50000
A32: Owner 2 Annual Salary | B32: 50000
A33: Studio Manager Hourly | B33: 25
A34: Studio Manager Hours/Week | B34: 0
A35: Teacher Hourly | B35: 23
A36: Assistant Hourly | B36: 15
A37: Payroll Tax Rate | B37: 0.0765
A39: EVENTS & WORKSHOPS
A40: Paint & Sip Events/Month | B40: 8
A41: Paint & Sip Price | B41: 55
A42: Paint & Sip Attendance | B42: 20
A43: Private Events/Month | B43: 3
A44: Private Event Base Fee | B44: 99
A45: Private Event Per Person | B45: 15
...

Sheet Class Schedule
A1: REGULAR CLASS SCHEDULE - Per-Year Enrollment Tracking
A3: Category | B3: Duration (hrs) | C3: Price | D3: Max Students | E3: Sessions/Yr | F3: Yr1 Enrolled | G3: Yr1 % | H3: Yr2 Enrolled | I3: Yr2 % | J3: Yr3 Enrolled | K3: Yr3 % | L3: Yr4 Enrolled | M3: Yr4 % | N3: Yr5 Enrolled | O3: Yr5 % | P3: Notes
A4: Adults - Painting | B4: 2 | C4: 199 | D4: 12 | E4: 12 | F4: 6 | G4: =F4/$D4 -> 0.5 | H4: 7 | I4: =H4/$D4 -> 0.58333333 | J4: 8 | K4: =J4/$D4 -> 0.66666667 | L4: 10 | M4: =L4/$D4 -> 0.83333333 | N4: 12 | O4: =N4/$D4 -> 1 | P4: 2hr session
A5: Adults - Pottery | B5: 2.5 | C5: 229 | D5: 8 | E5: 12 | F5: 3 | G5: =F5/$D5 -> 0.375 | H5: 4 | I5: =H5/$D5 -> 0.5 | J5: 5 | K5: =J5/$D5 -> 0.625 | L5: 6 | M5: =L5/$D5 -> 0.75 | N5: 6 | O5: =N5/$D5 -> 0.75 | P5: 2.5hr session
A6: Teens 13-18 - Drawing | B6: 2 | C6: 199 | D6: 15 | E6: 12 | F6: 8 | G6: =F6/$D6 -> 0.53333333 | H6: 10 | I6: =H6/$D6 -> 0.66666667 | J6: 12 | K6: =J6/$D6 -> 0.8 | L6: 14 | M6: =L6/$D6 -> 0.93333333 | N6: 15 | O6: =N6/$D6 -> 1 | P6: 2hr session
A7: Teens 13-18 - Pottery | B7: 2 | C7: 229 | D7: 8 | E7: 12 | F7: 3 | G7: =F7/$D7 -> 0.375 | H7: 4 | I7: =H7/$D7 -> 0.5 | J7: 5 | K7: =J7/$D7 -> 0.625 | L7: 6 | M7: =L7/$D7 -> 0.75 | N7: 6 | O7: =N7/$D7 -> 0.75 | P7: 2hr session
A8: Kids 9-12 - Mixed Media | B8: 1.5 | C8: 159 | D8: 12 | E8: 12 | F8: 6 | G8: =F8/$D8 -> 0.5 | H8: 7 | I8: =H8/$D8 -> 0.58333333 | J8: 8 | K8: =J8/$D8 -> 0.66666667 | L8: 10 | M8: =L8/$D8 -> 0.83333333 | N8: 12 | O8: =N8/$D8 -> 1 | P8: 1.5hr session
A9: Kids 9-12 - Pottery | B9: 1.5 | C9: 179 | D9: 6 | E9: 12 | F9: 3 | G9: =F9/$D9 -> 0.5 | H9: 4 | I9: =H9/$D9 -> 0.66666667 | J9: 5 | K9: =J9/$D9 -> 0.83333333 | L9: 6 | M9: =L9/$D9 -> 1 | N9: 6 | O9: =N9/$D9 -> 1 | P9: 1.5hr session
A10: Kids 6-8 - General Art | B10: 1.5 | C10: 154 | D10: 12 | E10: 12 | F10: 6 | G10: =F10/$D10 -> 0.5 | H10: 7 | I10: =H10/$D10 -> 0.58333333 | J10: 8 | K10: =J10/$D10 -> 0.66666667 | L10: 10 | M10: =L10/$D10 -> 0.83333333 | N10: 12 | O10: =N10/$D10 -> 1 | P10: 1hr session
A11: Kids 4-5 - General Art | B11: 1.5 | C11: 154 | D11: 12 | E11: 12 | F11: 6 | G11: =F11/$D11 -> 0.5 | H11: 7 | I11: =H11/$D11 -> 0.58333333 | J11: 8 | K11: =J11/$D11 -> 0.66666667 | L11: 10 | M11: =L11/$D11 -> 0.83333333 | N11: 12 | O11: =N11/$D11 -> 1 | P11: 1hr session
A12: Homeschool 6-12 | B12: 1.5 | C12: 154 | D12: 12 | E12: 12 | F12: 6 | G12: =F12/$D12 -> 0.5 | H12: 7 | I12: =H12/$D12 -> 0.58333333 | J12: 8 | K12: =J12/$D12 -> 0.66666667 | L12: 10 | M12: =L12/$D12 -> 0.83333333 | N12: 12 | O12: =N12/$D12 -> 1 | P12: 1.5hr session
A13: Homeschool Teens | B13: 1.5 | C13: 154 | D13: 12 | E13: 12 | F13: 6 | G13: =F13/$D13 -> 0.5 | H13: 7 | I13: =H13/$D13 -> 0.58333333 | J13: 8 | K13: =J13/$D13 -> 0.66666667 | L13: 10 | M13: =L13/$D13 -> 0.83333333 | N13: 12 | O13: =N13/$D13 -> 1 | P13: 1.5hr session
A14: Adults - Ceramics (Non-Wheel) | B14: 2 | C14: 229 | D14: 8 | E14: 12 | F14: 6 | G14: =F14/$D14 -> 0.75 | H14: 7 | I14: =H14/$D14 -> 0.875 | J14: 8 | K14: =J14/$D14 -> 1 | L14: 10 | M14: =L14/$D14 -> 1.25 | N14: 12 | O14: =N14/$D14 -> 1.5 | P14: 2hr session
A15: Teens 13-18 - Ceramics (Non-Wheel) | B15: 2 | C15: 229
A16: Kids 9-12 - Ceramics (Non-Wheel) | B16: 2 | C16: 179
A18: INSTRUCTIONS:
A19: • Edit "Enrolled" columns (light green) to set student numbers per year
A20: • Percentages auto-calculate: Enrolled / Max Students
A21: • Max Students stays constant; enrollment can grow each year
A22: • Year 1 = 6 sessions (Mar-Apr, Sep-Dec); Year 2+ = 12 sessions
A23: • Add rows if you need more class types

Sheet Summer Camps
A1: SUMMER CAMP SCHEDULE - Per-Year Enrollment Tracking
A3: Age Group | B3: Duration | C3: Days | D3: Type | E3: Price | F3: Max Students | G3: Weeks | H3: Yr1 Enrolled | I3: Yr1 % | J3: Yr2 Enrolled | K3: Yr2 % | L3: Yr3 Enrolled | M3: Yr3 % | N3: Yr4 Enrolled | O3: Yr4 % | P3: Yr5 Enrolled | Q3: Yr5 %
A4: 45784 | B4: Half Day AM | C4: 5 | D4: General | E4: 159 | F4: 12 | G4: 11 | H4: 0 | I4: 0.6 | J4: 0 | K4: 0.65 | L4: 0 | M4: =L4/$F4 -> 0 | N4: 0 | O4: =N4/$F4 -> 0 | P4: 0 | Q4: =P4/$F4 -> 0
A5: 45784 | B5: Half Day | C5: 5 | D5: Ceramics | E5: 189 | F5: 8 | G5: 11 | H5: 0 | I5: =H5/$F5 -> 0 | J5: 0 | K5: =J5/$F5 -> 0 | L5: 0 | M5: =L5/$F5 -> 0 | N5: 0 | O5: =N5/$F5 -> 0 | P5: 0 | Q5: =P5/$F5 -> 0
A6: 45784 | B6: Half Day | C6: 4 | D6: General | E6: 135 | F6: 12 | G6: 11 | H6: 0 | I6: 0.6 | J6: 0 | K6: =J6/$F6 -> 0 | L6: 0 | M6: =L6/$F6 -> 0 | N6: 0 | O6: =N6/$F6 -> 0 | P6: 0 | Q6: =P6/$F6 -> 0
A7: 45784 | B7: Full Day | C7: 5 | D7: General | E7: 275 | F7: 15 | G7: 11 | H7: 8 | I7: 0.6 | J7: 10 | K7: =J7/$F7 -> 0.66666667 | L7: 8 | M7: =L7/$F7 -> 0.53333333 | N7: 10 | O7: =N7/$F7 -> 0.66666667 | P7: 12 | Q7: =P7/$F7 -> 0.8
A8: 45784 | B8: Full Day | C8: 5 | D8: Ceramics | E8: 295 | F8: 12 | G8: 11 | H8: 7 | I8: =H8/$F8 -> 0.58333333 | J8: 7 | K8: =J8/$F8 -> 0.58333333 | L8: 6 | M8: =L8/$F8 -> 0.5 | N8: 7 | O8: =N8/$F8 -> 0.58333333 | P8: 8 | Q8: =P8/$F8 -> 0.66666667
A9: 45881 | B9: Half Day | C9: 5 | D9: General | E9: 159 | F9: 12 | G9: 11 | H9: 0 | I9: 0.6 | J9: 0 | K9: =J9/$F9 -> 0 | L9: 0 | M9: =L9/$F9 -> 0 | N9: 0 | O9: =N9/$F9 -> 0 | P9: 0 | Q9: =P9/$F9 -> 0
A10: 45881 | B10: Half Day | C10: 5 | D10: Ceramics | E10: 189 | F10: 8 | G10: 11 | H10: 0 | I10: =H10/$F10 -> 0 | J10: 0 | K10: =J10/$F10 -> 0 | L10: 0 | M10: =L10/$F10 -> 0 | N10: 0 | O10: =N10/$F10 -> 0 | P10: 0 | Q10: =P10/$F10 -> 0
A11: 45881 | B11: Half Day | C11: 4 | D11: General | E11: 135 | F11: 12 | G11: 11 | H11: 0 | I11: 0.6 | J11: 0 | K11: =J11/$F11 -> 0 | L11: 0 | M11: =L11/$F11 -> 0 | N11: 0 | O11: =N11/$F11 -> 0 | P11: 0 | Q11: =P11/$F11 -> 0
A12: 45881 | B12: Full Day | C12: 5 | D12: General | E12: 275 | F12: 15 | G12: 11 | H12: 8 | I12: 0.6 | J12: 10 | K12: =J12/$F12 -> 0.66666667 | L12: 8 | M12: =L12/$F12 -> 0.53333333 | N12: 10 | O12: =N12/$F12 -> 0.66666667 | P12: 12 | Q12: =P12/$F12 -> 0.8
A13: 45881 | B13: Full Day | C13: 5 | D13: Ceramics | E13: 295 | F13: 6 | G13: 11 | H13: 0 | I13: =H13/$F13 -> 0 | J13: 5 | K13: =J13/$F13 -> 0.83333333 | L13: 6 | M13: =L13/$F13 -> 1 | N13: 7 | O13: =N13/$F13 -> 1.1666667 | P13: 8 | Q13: =P13/$F13 -> 1.3333333
A14: 45881 | B14: Full Day | C14: 4 | D14: General | E14: 234 | F14: 15 | G14: 11 | H14: 8 | I14: 0.6 | J14: 10 | K14: =J14/$F14 -> 0.66666667 | L14: 8 | M14: =L14/$F14 -> 0.53333333 | N14: 10 | O14: =N14/$F14 -> 0.66666667 | P14: 12 | Q14: =P14/$F14 -> 0.8
A15: 46007 | B15: Half Day | C15: 5 | D15: General | E15: 159 | F15: 15 | G15: 11 | H15: 0 | I15: 0.6 | J15: 0 | K15: =J15/$F15 -> 0 | L15: 0 | M15: =L15/$F15 -> 0 | N15: 0 | O15: =N15/$F15 -> 0 | P15: 0 | Q15: =P15/$F15 -> 0
A16: 46007 | B16: Half Day | C16: 5 | D16: Ceramics | E16: 189 | F16: 10 | G16: 11 | H16: 0 | I16: =H16/$F16 -> 0 | J16: 0 | K16: =J16/$F16 -> 0 | L16: 0 | M16: =L16/$F16 -> 0 | N16: 0 | O16: =N16/$F16 -> 0 | P16: 0 | Q16: =P16/$F16 -> 0
A17: 46007 | B17: Full Day | C17: 5 | D17: General | E17: 275 | F17: 15 | G17: 11 | H17: 8 | I17: 0.6 | J17: 12 | K17: =J17/$F17 -> 0.8 | L17: 12 | M17: =L17/$F17 -> 0.8 | N17: 14 | O17: =N17/$F17 -> 0.93333333 | P17: 15 | Q17: =P17/$F17 -> 1
A18: 46007 | B18: Full Day | C18: 5 | D18: Ceramics | E18: 295 | F18: 6 | G18: 11 | H18: 4 | I18: =H18/$F18 -> 0.66666667 | J18: 8 | K18: =J18/$F18 -> 1.3333333 | L18: 7 | M18: =L18/$F18 -> 1.1666667 | N18: 8 | O18: =N18/$F18 -> 1.3333333 | P18: 10 | Q18: =P18/$F18 -> 1.6666667
A19: All Ages | B19: Extended Care | C19: 5 | D19: Add-on | E19: 50 | F19: 20 | G19: 11 | H19: 10 | I19: =H19/$F19 -> 0.5 | J19: 15 | K19: =J19/$F19 -> 0.75 | L19: 14 | M19: =L19/$F19 -> 0.7 | N19: 17 | O19: =N19/$F19 -> 0.85 | P19: 20 | Q19: =P19/$F19 -> 1
A21: INSTRUCTIONS:
A22: • Edit "Enrolled" columns (light orange) to set student numbers per year
A23: • Percentages auto-calculate: Enrolled / Max Students
A24: • Max Students stays constant; enrollment can grow each year
A25: • Add rows if you need more camp types

Sheet Startup Supplies
A1: STARTUP ART SUPPLIES
A3: Category | B3: Item | C3: Quantity | D3: Unit Price | E3: Total
A4: CANVAS
B5: Canvas 8x10 | C5: 100 | D5: 3.5 | E5: =C5*D5 -> 350
B6: Canvas 11x14 | C6: 100 | D6: 5 | E6: =C6*D6 -> 500
B7: Canvas 16x20 | C7: 50 | D7: 8.5 | E7: =C7*D7 -> 425
B8: Canvas 18x24 | C8: 0 | D8: 11 | E8: =C8*D8 -> 0
B9: CANVAS SUBTOTAL | E9: =SUM(E5:E8) -> 1275
A11: PAPER
B12: Drawing Paper 9x12 (500 sheets) | C12: 10 | D12: 25 | E12: =C12*D12 -> 250
B13: Watercolor Paper 9x12 (100) | C13: 20 | D13: 18 | E13: =C13*D13 -> 360
B14: Mixed Media Paper 11x14 (100) | C14: 15 | D14: 22 | E14: =C14*D14 -> 330
B15: Cardstock Variety Pack | C15: 20 | D15: 15 | E15: =C15*D15 -> 300
B16: PAPER SUBTOTAL | E16: =SUM(E12:E15) -> 1240
A18: PAINT
B19: Acrylic Paint Set (24 colors) | C19: 50 | D19: 28 | E19: =C19*D19 -> 1400
B20: Tempera Paint Gallon (assorted) | C20: 40 | D20: 12 | E20: =C20*D20 -> 480
B21: Watercolor Sets (24 pan) | C21: 50 | D21: 15 | E21: =C21*D21 -> 750
B22: Oil Paint Set (12 tubes) | C22: 20 | D22: 45 | E22: =C22*D22 -> 900
B23: PAINT SUBTOTAL | E23: =SUM(E19:E22) -> 3530
A25: BRUSHES
B26: Brush Sets (variety 10pc) | C26: 40 | D26: 12 | E26: =C26*D26 -> 480
B27: Detail Brush Sets | C27: 40 | D27: 8 | E27: =C27*D27 -> 320
B28: Foam Brushes (100 pack) | C28: 10 | D28: 15 | E28: =C28*D28 -> 150
B29: BRUSH SUBTOTAL | E29: =SUM(E26:E28) -> 950
A31: DRAWING SUPPLIES
B32: Pencil Sets (12pc graphite) | C32: 75 | D32: 8 | E32: =C32*D32 -> 600
B33: Colored Pencil Sets (24) | C33: 75 | D33: 12 | E33: =C33*D33 -> 900
B34: Charcoal Sets | C34: 50 | D34: 10 | E34: =C34*D34 -> 500
B35: Pastels (oil & soft) | C35: 50 | D35: 18 | E35: =C35*D35 -> 900
B36: Erasers (variety) | C36: 100 | D36: 1.5 | E36: =C36*D36 -> 150
B37: DRAWING SUBTOTAL | E37: =SUM(E32:E36) -> 3050
A39: MARKERS & INK
B40: Marker Sets (washable, 24) | C40: 75 | D40: 8 | E40: =C40*D40 -> 600
B41: Fine Point Markers (12) | C41: 75 | D41: 6 | E41: =C41*D41 -> 450
B42: India Ink (bottles) | C42: 40 | D42: 8 | E42: =C42*D42 -> 320
B43: MARKER SUBTOTAL | E43: =SUM(E40:E42) -> 1370
A45: CLAY & POTTERY
B46: Clay (25lb bags) | C46: 100 | D46: 12.5 | E46: =C46*D46 -> 1250
B47: Glazes (assorted pints) | C47: 75 | D47: 12 | E47: =C47*D47 -> 900
...

Sheet Revenue Model
A1: DECO ART CENTER - REVENUE PROJECTIONS
A3: Revenue Source | B3: Year 1 (10mo) | C3: Year 2 | D3: Year 3 | E3: Year 4 | F3: Year 5
A4: REGULAR CLASSES
A5: Classes Revenue | B5: =SUMPRODUCT('Class Schedule'!C4:C13,'Class Schedule'!F4:F13)*Assumptions!$B$13 -> 56082 | C5: =SUMPRODUCT('Class Schedule'!C4:C13,'Class Schedule'!H4:H13)*Assumptions!$B$14 -> 136272 | D5: =SUMPRODUCT('Class Schedule'!C4:C13,'Class Schedule'!J4:J13)*Assumptions!$B$14 -> 160380 | E5: =SUMPRODUCT('Class Schedule'!C4:C13,'Class Schedule'!L4:L13)*Assumptions!$B$14 -> 196176 | F5: =SUMPRODUCT('Class Schedule'!C4:C13,'Class Schedule'!N4:N13)*Assumptions!$B$14 -> 221940
A6: - Pottery Classes Only | B6: =('Class Schedule'!C5*'Class Schedule'!F5+'Class Schedule'!C7*'Class Schedule'!F7+'Class Schedule'!C9*'Class Schedule'!F9)*Assumptions!$B$13 -> 11466 | C6: =('Class Schedule'!C5*'Class Schedule'!H5+'Class Schedule'!C7*'Class Schedule'!H7+'Class Schedule'!C9*'Class Schedule'!H9)*Assumptions!$B$14 -> 30576 | D6: =('Class Schedule'!C5*'Class Schedule'!J5+'Class Schedule'!C7*'Class Schedule'!J7+'Class Schedule'!C9*'Class Schedule'!J9)*Assumptions!$B$14 -> 38220 | E6: =('Class Schedule'!C5*'Class Schedule'!L5+'Class Schedule'!C7*'Class Schedule'!L7+'Class Schedule'!C9*'Class Schedule'!L9)*Assumptions!$B$14 -> 45864 | F6: =('Class Schedule'!C5*'Class Schedule'!N5+'Class Schedule'!C7*'Class Schedule'!N7+'Class Schedule'!C9*'Class Schedule'!N9)*Assumptions!$B$14 -> 45864
A7: Drop-in Classes | B7: =B5*Assumptions!$B$28*0.25 -> 701.025 | C7: =C5*Assumptions!$B$28*0.25 -> 1703.4 | D7: =D5*Assumptions!$B$28*0.25 -> 2004.75 | E7: =E5*Assumptions!$B$28*0.25 -> 2452.2 | F7: =F5*Assumptions!$B$28*0.25 -> 2774.25
A9: SUMMER CAMPS
A10: Summer Camps Revenue | B10: =SUMPRODUCT('Summer Camps'!E4:E19,'Summer Camps'!H4:H19,'Summer Camps'!G4:G19) -> 134387 | C10: =SUMPRODUCT('Summer Camps'!E4:E19,'Summer Camps'!J4:J19,'Summer Camps'!G4:G19) -> 195690 | D10: =SUMPRODUCT('Summer Camps'!E4:E19,'Summer Camps'!L4:L19,'Summer Camps'!G4:G19) -> 174647 | E10: =SUMPRODUCT('Summer Camps'!E4:E19,'Summer Camps'!N4:N19,'Summer Camps'!G4:G19) -> 209330 | F10: =SUMPRODUCT('Summer Camps'!E4:E19,'Summer Camps'!P4:P19,'Summer Camps'!G4:G19) -> 244233
A11: - Ceramics Camps Only | B11: =('Summer Camps'!E5*'Summer Camps'!H5*'Summer Camps'!G5+'Summer Camps'!E6*'Summer Camps'!H6*'Summer Camps'!G6+'Summer Camps'!E8*'Summer Camps'!H8*'Summer Camps'!G8+'Summer Camps'!E10*'Summer Camps'!H10*'Summer Camps'!G10+'Summer Camps'!E14*'Summer Camps'!H14*'Summer Camps'!G14+'Summer Camps'!E16*'Summer Camps'!H16*'Summer Camps'!G16) -> 43307 | C11: =('Summer Camps'!E5*'Summer Camps'!J5*'Summer Camps'!G5+'Summer Camps'!E6*'Summer Camps'!J6*'Summer Camps'!G6+'Summer Camps'!E8*'Summer Camps'!J8*'Summer Camps'!G8+'Summer Camps'!E10*'Summer Camps'!J10*'Summer Camps'!G10+'Summer Camps'!E14*'Summer Camps'!J14*'Summer Camps'!G14+'Summer Camps'!E16*'Summer Camps'!J16*'Summer Camps'!G16) -> 48455 | D11: =('Summer Camps'!E5*'Summer Camps'!L5*'Summer Camps'!G5+'Summer Camps'!E6*'Summer Camps'!L6*'Summer Camps'!G6+'Summer Camps'!E8*'Summer Camps'!L8*'Summer Camps'!G8+'Summer Camps'!E10*'Summer Camps'!L10*'Summer Camps'!G10+'Summer Camps'!E14*'Summer Camps'!L14*'Summer Camps'!G14+'Summer Camps'!E16*'Summer Camps'!L16*'Summer Camps'!G16) -> 40062 | E11: =('Summer Camps'!E5*'Summer Camps'!N5*'Summer Camps'!G5+'Summer Camps'!E6*'Summer Camps'!N6*'Summer Camps'!G6+'Summer Camps'!E8*'Summer Camps'!N8*'Summer Camps'!G8+'Summer Camps'!E10*'Summer Camps'!N10*'Summer Camps'!G10+'Summer Camps'!E14*'Summer Camps'!N14*'Summer Camps'!G14+'Summer Camps'!E16*'Summer Camps'!N16*'Summer Camps'!G16) -> 48455 | F11: =('Summer Camps'!E5*'Summer Camps'!P5*'Summer Camps'!G5+'Summer Camps'!E6*'Summer Camps'!P6*'Summer Camps'!G6+'Summer Camps'!E8*'Summer Camps'!P8*'Summer Camps'!G8+'Summer Camps'!E10*'Summer Camps'!P10*'Summer Camps'!G10+'Summer Camps'!E14*'Summer Camps'!P14*'Summer Camps'!G14+'Summer Camps'!E16*'Summer Camps'!P16*'Summer Camps'!G16) -> 56848
A13: EVENTS & WORKSHOPS
A14: Paint & Sip Events | B14: =Assumptions!$B$40*Assumptions!$B$41*Assumptions!$B$42*10 -> 88000 | C14: =Assumptions!$B$40*Assumptions!$B$41*Assumptions!$B$42*12 -> 105600 | D14: =C14 -> 105600 | E14: =C14 -> 105600 | F14: =C14 -> 105600
A15: Private Events | B15: =(Assumptions!$B$44+Assumptions!$B$45*Assumptions!$B$46)*Assumptions!$B$43*10 -> 9720 | C15: =(Assumptions!$B$44+Assumptions!$B$45*Assumptions!$B$46)*Assumptions!$B$43*12 -> 11664 | D15: =C15 -> 11664 | E15: =C15 -> 11664 | F15: =C15 -> 11664
A16: Visiting Artist Workshops | B16: =Assumptions!$B$48*Assumptions!$B$49*Assumptions!$B$47*10 -> 22500 | C16: =Assumptions!$B$48*Assumptions!$B$49*Assumptions!$B$47*12 -> 27000 | D16: =C16 -> 27000 | E16: =C16 -> 27000 | F16: =C16 -> 27000
A18: BEVERAGE SALES
A19: Paint & Sip Beverages | B19: =Assumptions!$B$40*Assumptions!$B$42*Assumptions!$B$52*(Assumptions!$B$57*0.6+Assumptions!$B$56*0.4)*10 -> 26240 | C19: =Assumptions!$B$40*Assumptions!$B$42*Assumptions!$B$52*(Assumptions!$B$57*0.6+Assumptions!$B$56*0.4)*12 -> 31488 | D19: =C19 -> 31488 | E19: =C19 -> 31488 | F19: =C19 -> 31488
A20: Private Event Beverages | B20: =Assumptions!$B$43*Assumptions!$B$46*Assumptions!$B$53*(Assumptions!$B$57*0.6+Assumptions!$B$56*0.4)*10 -> 7380 | C20: =Assumptions!$B$43*Assumptions!$B$46*Assumptions!$B$53*(Assumptions!$B$57*0.6+Assumptions!$B$56*0.4)*12 -> 8856 | D20: =C20 -> 8856 | E20: =C20 -> 8856 | F20: =C20 -> 8856
A21: Workshop Beverages | B21: =Assumptions!$B$47*Assumptions!$B$49*Assumptions!$B$54*((Assumptions!$B$55*0.5)+(Assumptions!$B$57*0.25+Assumptions!$B$56*0.25))*10 -> 2700 | C21: =Assumptions!$B$47*Assumptions!$B$49*Assumptions!$B$54*((Assumptions!$B$55*0.5)+(Assumptions!$B$57*0.25+Assumptions!$B$56*0.25))*12 -> 3240 | D21: =C21 -> 3240 | E21: =C21 -> 3240 | F21: =C21 -> 3240
A23: RETAIL
A24: Retail Sales (5% of program revenue) | B24: =SUM(B5:B23)*0.05 -> 20124.151 | C24: =SUM(C5:C23)*0.05 -> 30027.22 | D24: =SUM(D5:D23)*0.05 -> 30158.088 | E24: =SUM(E5:E23)*0.05 -> 34506.26 | F24: =SUM(F5:F23)*0.05 -> 37975.363
A26: TOTAL GROSS REVENUE | B26: =SUM(B5:B24) -> 422607.18 | C26: =SUM(C5:C24) -> 630571.62 | D26: =SUM(D5:D24) -> 633319.84 | E26: =SUM(E5:E24) -> 724631.46 | F26: =SUM(F5:F24) -> 797482.61

Sheet Expenses
A1: DECO ART CENTER - OPERATING EXPENSES
A3: Expense Category | B3: Year 1 (10mo) | C3: Year 2 | D3: Year 3 | E3: Year 4 | F3: Year 5
A4: COST OF GOODS SOLD
A5: Art Supplies (15% of non-pottery program revenue) | B5: =('Revenue Model'!B26-('Revenue Model'!B19+'Revenue Model'!B20+'Revenue Model'!B21)-'Revenue Model'!B24-('Revenue Model'!B6+'Revenue Model'!B12))*Assumptions!$B$61 -> 28375.762 | C5: =('Revenue Model'!C26-('Revenue Model'!C19+'Revenue Model'!C20+'Revenue Model'!C21)-'Revenue Model'!C24-('Revenue Model'!C6+'Revenue Model'!C12))*Assumptions!$B$61 -> 42110.752 | D5: =('Revenue Model'!D26-('Revenue Model'!D19+'Revenue Model'!D20+'Revenue Model'!D21)-'Revenue Model'!D24-('Revenue Model'!D6+'Revenue Model'!D12))*Assumptions!$B$61 -> 41708.62 | E5: =('Revenue Model'!E26-('Revenue Model'!E19+'Revenue Model'!E20+'Revenue Model'!E21)-'Revenue Model'!E24-('Revenue Model'!E6+'Revenue Model'!E12))*Assumptions!$B$61 -> 48054.176 | F5: =('Revenue Model'!F26-('Revenue Model'!F19+'Revenue Model'!F20+'Revenue Model'!F21)-'Revenue Model'!F24-('Revenue Model'!F6+'Revenue Model'!F12))*Assumptions!$B$61 -> 53604.74
A6: Pottery Supplies (12% of pottery classes/camps) | B6: =('Revenue Model'!B6+'Revenue Model'!B12)*Assumptions!$B$62 -> 917.28 | C6: =('Revenue Model'!C6+'Revenue Model'!C12)*Assumptions!$B$62 -> 2446.08 | D6: =('Revenue Model'!D6+'Revenue Model'!D12)*Assumptions!$B$62 -> 3057.6 | E6: =('Revenue Model'!E6+'Revenue Model'!E12)*Assumptions!$B$62 -> 3669.12 | F6: =('Revenue Model'!F6+'Revenue Model'!F12)*Assumptions!$B$62 -> 3669.12
A7: Beverage COGS | B7: =('Revenue Model'!B19+'Revenue Model'!B20+'Revenue Model'!B21)*Assumptions!$B$58 -> 10896 | C7: =('Revenue Model'!C19+'Revenue Model'!C20+'Revenue Model'!C21)*Assumptions!$B$58 -> 13075.2 | D7: =('Revenue Model'!D19+'Revenue Model'!D20+'Revenue Model'!D21)*Assumptions!$B$58 -> 13075.2 | E7: =('Revenue Model'!E19+'Revenue Model'!E20+'Revenue Model'!E21)*Assumptions!$B$58 -> 13075.2 | F7: =('Revenue Model'!F19+'Revenue Model'!F20+'Revenue Model'!F21)*Assumptions!$B$58 -> 13075.2
A8: Supplies Replenishment (Quarterly) | B8: ='Startup Supplies'!E66*Assumptions!$B$63*3 -> 0 | C8: ='Startup Supplies'!E66*Assumptions!$B$63*4 -> 0 | D8: ='Startup Supplies'!E66*Assumptions!$B$63*4 -> 0 | E8: ='Startup Supplies'!E66*Assumptions!$B$63*4 -> 0 | F8: ='Startup Supplies'!E66*Assumptions!$B$63*4 -> 0
A10: PAYROLL & LABOR
A11: Owner Salaries | B11: =Assumptions!$B$31+Assumptions!$B$32 -> 100000 | C11: =Assumptions!$B$31+Assumptions!$B$32 -> 100000 | D11: =Assumptions!$B$31+Assumptions!$B$32 -> 100000 | E11: =Assumptions!$B$31+Assumptions!$B$32 -> 100000 | F11: =Assumptions!$B$31+Assumptions!$B$32 -> 100000
A12: Studio Manager | B12: 0 | C12: =Assumptions!$B$33*Assumptions!$B$34*52 -> 0 | D12: =Assumptions!$B$33*Assumptions!$B$34*52 -> 0 | E12: =Assumptions!$B$33*Assumptions!$B$34*52 -> 0 | F12: =Assumptions!$B$33*Assumptions!$B$34*52 -> 0
A13: Teachers (calculated from enrollment) | B13: =(SUMPRODUCT('Class Schedule'!B4:B13,'Class Schedule'!F4:F13)*Assumptions!$B$13 + SUMPRODUCT('Summer Camps'!H4:H19,'Summer Camps'!G4:G19)*5)*Assumptions!$B$35 -> 79603 | C13: =(SUMPRODUCT('Class Schedule'!B4:B13,'Class Schedule'!H4:H13)*Assumptions!$B$14 + SUMPRODUCT('Summer Camps'!J4:J19,'Summer Camps'!G4:G19)*5)*Assumptions!$B$35 -> 127903 | D13: =(SUMPRODUCT('Class Schedule'!B4:B13,'Class Schedule'!J4:J13)*Assumptions!$B$14 + SUMPRODUCT('Summer Camps'!L4:L19,'Summer Camps'!G4:G19)*5)*Assumptions!$B$35 -> 123165 | E13: =(SUMPRODUCT('Class Schedule'!B4:B13,'Class Schedule'!L4:L13)*Assumptions!$B$14 + SUMPRODUCT('Summer Camps'!N4:N19,'Summer Camps'!G4:G19)*5)*Assumptions!$B$35 -> 148879 | F13: =(SUMPRODUCT('Class Schedule'!B4:B13,'Class Schedule'!N4:N13)*Assumptions!$B$14 + SUMPRODUCT('Summer Camps'!P4:P19,'Summer Camps'!G4:G19)*5)*Assumptions!$B$35 -> 172385
A14: Assistants (for classes >10 students) | B14: =B13*0.3 -> 23880.9 | C14: =C13*0.3 -> 38370.9 | D14: =D13*0.3 -> 36949.5 | E14: =E13*0.3 -> 44663.7 | F14: =F13*0.3 -> 51715.5
A15: Payroll Taxes | B15: =SUM(B11:B14)*Assumptions!$B$37 -> 15566.518 | C15: =SUM(C11:C14)*Assumptions!$B$37 -> 20369.953 | D15: =SUM(D11:D14)*Assumptions!$B$37 -> 19898.759 | E15: =SUM(E11:E14)*Assumptions!$B$37 -> 22456.017 | F15: =SUM(F11:F14)*Assumptions!$B$37 -> 24793.688
A17: FACILITIES & OCCUPANCY
A18: Rent (Base + NNN) | B18: =Assumptions!$B$8*10 -> 45000 | C18: =Assumptions!$B$8*12 -> 54000 | D18: =Assumptions!$B$8*12 -> 54000 | E18: =Assumptions!$B$8*12 -> 54000 | F18: =Assumptions!$B$8*12 -> 54000
A19: Loan Payment (Principal + Interest) | B19: =Assumptions!$B$23*10 -> 11720.394 | C19: =Assumptions!$B$23*12 -> 14064.473 | D19: =Assumptions!$B$23*12 -> 14064.473 | E19: =Assumptions!$B$23*12 -> 14064.473 | F19: =Assumptions!$B$23*12 -> 14064.473
A20: Insurance | B20: =Assumptions!$B$68*10 -> 5416.6667 | C20: =Assumptions!$B$68*12 -> 6500 | D20: =Assumptions!$B$68*12 -> 6500 | E20: =Assumptions!$B$68*12 -> 6500 | F20: =Assumptions!$B$68*12 -> 6500
A21: Utilities (Elec+Gas+Water+Internet) | B21: =(Assumptions!$B$64+Assumptions!$B$65+Assumptions!$B$66+Assumptions!$B$67)*10 -> 11000 | C21: =(Assumptions!$B$64+Assumptions!$B$65+Assumptions!$B$66+Assumptions!$B$67)*12 -> 13200 | D21: =(Assumptions!$B$64+Assumptions!$B$65+Assumptions!$B$66+Assumptions!$B$67)*12 -> 13200 | E21: =(Assumptions!$B$64+Assumptions!$B$65+Assumptions!$B$66+Assumptions!$B$67)*12 -> 13200 | F21: =(Assumptions!$B$64+Assumptions!$B$65+Assumptions!$B$66+Assumptions!$B$67)*12 -> 13200
A22: Repairs & Maintenance | B22: =Assumptions!$B$70/12*10 -> 4166.6667 | C22: =Assumptions!$B$70 -> 5000 | D22: =Assumptions!$B$70 -> 5000 | E22: =Assumptions!$B$70 -> 5000 | F22: =Assumptions!$B$70 -> 5000
A24: OPERATIONS
A25: Marketing & Advertising | B25: =Assumptions!$B$71*10 -> 15000 | C25: ='Revenue Model'!C26*Assumptions!$B$72 -> 18917.149 | D25: ='Revenue Model'!D26*Assumptions!$B$72 -> 18999.595 | E25: ='Revenue Model'!E26*Assumptions!$B$72 -> 21738.944 | F25: ='Revenue Model'!F26*Assumptions!$B$72 -> 23924.478
A26: Professional Services | B26: =(Assumptions!$B$73+Assumptions!$B$74+Assumptions!$B$75)/12*10 -> 6000 | C26: =Assumptions!$B$73+Assumptions!$B$74+Assumptions!$B$75 -> 7200 | D26: =Assumptions!$B$73+Assumptions!$B$74+Assumptions!$B$75 -> 7200 | E26: =Assumptions!$B$73+Assumptions!$B$74+Assumptions!$B$75 -> 7200 | F26: =Assumptions!$B$73+Assumptions!$B$74+Assumptions!$B$75 -> 7200
A27: Liquor License | B27: =Assumptions!$B$76/12*10 -> 858.33333 | C27: =Assumptions!$B$76 -> 1030 | D27: =Assumptions!$B$76 -> 1030 | E27: =Assumptions!$B$76 -> 1030 | F27: =Assumptions!$B$76 -> 1030
A28: Miscellaneous | B28: 2000 | C28: 3000 | D28: 3500 | E28: 4000 | F28: 4500
A30: TOTAL OPERATING EXPENSES | B30: =SUM(B5:B29) -> 360401.52 | C30: =SUM(C5:C29) -> 467187.51 | D30: =SUM(D5:D29) -> 461348.75 | E30: =SUM(E5:E29) -> 507530.63 | F30: =SUM(F5:F29) -> 548662.2

Sheet Startup Costs
A1: STARTUP COSTS & INITIAL INVESTMENT
A3: Item | B3: Amount
A4: MOVE-IN COSTS (LEASE)
A5: First Month Rent | B5: =Assumptions!B8 -> 4500
A6: Last Month Rent | B6: =Assumptions!B8 -> 4500
A7: Security Deposit | B7: =Assumptions!B8 -> 4500
A9: EQUIPMENT & FURNISHINGS
A10: Kiln | B10: 8000
A11: Pottery Wheels (6) | B11: 4800
A12: Classroom Furniture | B12: 2500
A13: Lobby Furniture | B13: 2500
A15: INITIAL SUPPLIES
A16: Art Supplies (from Startup Supplies sheet) | B16: ='Startup Supplies'!E63 -> 18575
A18: SETUP & PROFESSIONAL
A19: Leasehold Improvements | B19: 15000
A20: Signage & Branding | B20: 5000
A21: Initial Marketing | B21: 3000
A22: Legal & Permits | B22: 5000
A23: POS System & Software | B23: 3000
A25: WORKING CAPITAL
A26: Operating Reserve | B26: =Expenses!B30/Assumptions!B18 -> 120133.84
A28: TOTAL STARTUP COSTS (excl. reserve) | B28: =SUM(B5:B7)+SUM(B10:B13)+B16+SUM(B19:B23) -> 80875
A29: TOTAL LOAN NEEDED (with reserve) | B29: =B28+B26 -> 201008.84

Sheet Loan Amortization
A1: WORKING CAPITAL LOAN AMORTIZATION
A3: Loan Amount: | B3: =Assumptions!B20 -> 80875
A4: Interest Rate: | B4: =Assumptions!B22 -> 0.1225
A5: Term: | B5: =Assumptions!B21&" years" -> 10 years
A6: Monthly Payment: | B6: =Assumptions!B23 -> 1172.0394
A8: Year | B8: Principal | C8: Interest | D8: Total Payment | E8: Balance
A9: Initial | E9: =B3 -> 80875
A10: Year 1 | B10: =D10-C10 -> 1813.2067 | C10: =E9*$B$4 -> 9907.1875 | D10: =$B$6*10 -> 11720.394 | E10: =E9-B10 -> 79061.793
A11: Year 2 | B11: =D11-C11 -> 4379.4034 | C11: =E10*$B$4 -> 9685.0697 | D11: =$B$6*12 -> 14064.473 | E11: =E10-B11 -> 74682.39
A12: Year 3 | B12: =D12-C12 -> 4915.8803 | C12: =E11*$B$4 -> 9148.5928 | D12: =$B$6*12 -> 14064.473 | E12: =E11-B12 -> 69766.51
A13: Year 4 | B13: =D13-C13 -> 5518.0756 | C13: =E12*$B$4 -> 8546.3974 | D13: =$B$6*12 -> 14064.473 | E13: =E12-B13 -> 64248.434
A14: Year 5 | B14: =D14-C14 -> 6194.0399 | C14: =E13*$B$4 -> 7870.4332 | D14: =$B$6*12 -> 14064.473 | E14: =E13-B14 -> 58054.394

Sheet Profit & Loss
A1: PRO FORMA PROFIT & LOSS STATEMENT
B3: Year 1 (10mo) | C3: Year 2 | D3: Year 3 | E3: Year 4 | F3: Year 5
A4: GROSS REVENUE | B4: ='Revenue Model'!B26 -> 422607.18 | C4: ='Revenue Model'!C26 -> 630571.62 | D4: ='Revenue Model'!D26 -> 633319.84 | E4: ='Revenue Model'!E26 -> 724631.46 | F4: ='Revenue Model'!F26 -> 797482.61
A6: TOTAL EXPENSES | B6: =Expenses!B30 -> 360401.52 | C6: =Expenses!C30 -> 467187.51 | D6: =Expenses!D30 -> 461348.75 | E6: =Expenses!E30 -> 507530.63 | F6: =Expenses!F30 -> 548662.2
A8: EBITDA | B8: =B4-B6 -> 62205.655 | C8: =C4-C6 -> 163384.11 | D8: =D4-D6 -> 171971.09 | E8: =E4-E6 -> 217100.83 | F8: =F4-F6 -> 248820.41
A10: Depreciation | B10: =Assumptions!B81/12*10 -> 2952.381 | C10: =Assumptions!B81 -> 3542.8571 | D10: =Assumptions!B81 -> 3542.8571 | E10: =Assumptions!B81 -> 3542.8571 | F10: =Assumptions!B81 -> 3542.8571
A12: EBIT (Operating Income) | B12: =B8-B10 -> 59253.274 | C12: =C8-C10 -> 159841.26 | D12: =D8-D10 -> 168428.23 | E12: =E8-E10 -> 213557.97 | F12: =F8-F10 -> 245277.56
A14: Interest Expense | B14: ='Loan Amortization'!C10 -> 9907.1875 | C14: ='Loan Amortization'!C11 -> 9685.0697 | D14: ='Loan Amortization'!C12 -> 9148.5928 | E14: ='Loan Amortization'!C13 -> 8546.3974 | F14: ='Loan Amortization'!C14 -> 7870.4332
A16: NET INCOME (Before Tax) | B16: =B12-B14 -> 49346.087 | C16: =C12-C14 -> 150156.19 | D16: =D12-D14 -> 159279.64 | E16: =E12-E14 -> 205011.58 | F16: =F12-F14 -> 237407.12
A18: KEY METRICS
A19: EBITDA Margin % | B19: =B8/B4 -> 0.14719498 | C19: =C8/C4 -> 0.25910477 | D19: =D8/D4 -> 0.27153909 | E19: =E8/E4 -> 0.29960172 | F19: =F8/F4 -> 0.31200732
A20: Net Margin % | B20: =B16/B4 -> 0.11676585 | C20: =C16/C4 -> 0.23812709 | D20: =D16/D4 -> 0.25149953 | E20: =E16/E4 -> 0.2829184 | F20: =F16/F4 -> 0.29769567

Sheet Cash Flow
A1: CASH FLOW PROJECTION
B3: Year 1 (10mo) | C3: Year 2 | D3: Year 3 | E3: Year 4 | F3: Year 5
A4: OPERATING ACTIVITIES
A5: Net Income | B5: ='Profit & Loss'!B16 -> 49346.087 | C5: ='Profit & Loss'!C16 -> 150156.19 | D5: ='Profit & Loss'!D16 -> 159279.64 | E5: ='Profit & Loss'!E16 -> 205011.58 | F5: ='Profit & Loss'!F16 -> 237407.12
A6: Add: Depreciation | B6: ='Profit & Loss'!B10 -> 2952.381 | C6: ='Profit & Loss'!C10 -> 3542.8571 | D6: ='Profit & Loss'!D10 -> 3542.8571 | E6: ='Profit & Loss'!E10 -> 3542.8571 | F6: ='Profit & Loss'!F10 -> 3542.8571
A7: Cash from Operations | B7: =B5+B6 -> 52298.468 | C7: =C5+C6 -> 153699.04 | D7: =D5+D6 -> 162822.5 | E7: =E5+E6 -> 208554.43 | F7: =F5+F6 -> 240949.98
A9: FINANCING ACTIVITIES
A10: Principal Payments | B10: =-'Loan Amortization'!B10 -> -1813.2067 | C10: =-'Loan Amortization'!B11 -> -4379.4034 | D10: =-'Loan Amortization'!B12 -> -4915.8803 | E10: =-'Loan Amortization'!B13 -> -5518.0756 | F10: =-'Loan Amortization'!B14 -> -6194.0399
A12: NET CASH FLOW | B12: =B7+B10 -> 50485.261 | C12: =C7+C10 -> 149319.64 | D12: =D7+D10 -> 157906.62 | E12: =E7+E10 -> 203036.36 | F12: =F7+F10 -> 234755.94
A13: Beginning Cash Balance | B13: ='Startup Costs'!B26 -> 120133.84 | C13: =B13 -> 120133.84 | D13: =C13 -> 120133.84 | E13: =D13 -> 120133.84 | F13: =E13 -> 120133.84
A14: Ending Cash Balance | B14: =B12+B13 -> 170619.1 | C14: =C12+C13 -> 269453.48 | D14: =D12+D13 -> 278040.46 | E14: =E12+E13 -> 323170.2 | F14: =F12+F13 -> 354889.78

Sheet Dashboard
A1: DECO ART CENTER - FINANCIAL DASHBOARD
A3: EXECUTIVE SUMMARY - RENTAL MODEL
A5: Startup Costs (excl. reserve) | B5: ='Startup Costs'!B28 -> 80875
A6: Operating Reserve (4 months) | B6: ='Startup Costs'!B26 -> 120133.84
A7: Total Loan Amount | B7: =Assumptions!B19 -> 0
A8: Monthly Loan Payment | B8: =Assumptions!B22 -> 0.1225
A9: Monthly Rent (Base + NNN) | B9: =Assumptions!B8 -> 4500
A11: 5-YEAR FINANCIAL PERFORMANCE
A13: Metric | B13: Year 1 | C13: Year 2 | D13: Year 3 | E13: Year 4 | F13: Year 5
A14: Revenue | B14: ='Revenue Model'!B26 -> 422607.18 | C14: ='Revenue Model'!C26 -> 630571.62 | D14: ='Revenue Model'!D26 -> 633319.84 | E14: ='Revenue Model'!E26 -> 724631.46 | F14: ='Revenue Model'!F26 -> 797482.61
A15: Expenses | B15: =Expenses!B35 | C15: =Expenses!C35 | D15: =Expenses!D35 | E15: =Expenses!E35 | F15: =Expenses!F35
A16: EBITDA | B16: ='Profit & Loss'!B8 -> 62205.655 | C16: ='Profit & Loss'!C8 -> 163384.11 | D16: ='Profit & Loss'!D8 -> 171971.09 | E16: ='Profit & Loss'!E8 -> 217100.83 | F16: ='Profit & Loss'!F8 -> 248820.41
A17: Net Income | B17: ='Profit & Loss'!B16 -> 49346.087 | C17: ='Profit & Loss'!C16 -> 150156.19 | D17: ='Profit & Loss'!D16 -> 159279.64 | E17: ='Profit & Loss'!E16 -> 205011.58 | F17: ='Profit & Loss'!F16 -> 237407.12
A18: Cash Flow | B18: ='Cash Flow'!B12 -> 50485.261 | C18: ='Cash Flow'!C12 -> 149319.64 | D18: ='Cash Flow'!D12 -> 157906.62 | E18: ='Cash Flow'!E12 -> 203036.36 | F18: ='Cash Flow'!F12 -> 234755.94
A20: KEY RATIOS
A22: Metric | B22: Year 1 | C22: Year 2 | D22: Year 3 | E22: Year 4 | F22: Year 5
A23: EBITDA Margin | B23: ='Profit & Loss'!B19 -> 0.14719498 | C23: ='Profit & Loss'!C19 -> 0.25910477 | D23: ='Profit & Loss'!D19 -> 0.27153909 | E23: ='Profit & Loss'!E19 -> 0.29960172 | F23: ='Profit & Loss'!F19 -> 0.31200732
A24: Net Margin | B24: ='Profit & Loss'!B20 -> 0.11676585 | C24: ='Profit & Loss'!C20 -> 0.23812709 | D24: ='Profit & Loss'!D20 -> 0.25149953 | E24: ='Profit & Loss'!E20 -> 0.2829184 | F24: ='Profit & Loss'!F20 -> 0.29769567
A26: NOTES FOR LENDERS:
A27: • Conservative 50% capacity Year 1, growing 20% annually
A28: • Multiple revenue streams (classes, camps, events, beverages, retail)
A29: • All pricing based on Tulsa market research
A30: • Year 1 = 10 months operation (March-December 2026)
A31: • 3-month operating reserve included in startup costs
